Workbook
Name ___INDEX_SHEET___ASAP_Utilities: #REF!
Name ___INDEX_SHEET___ASAP_Utilities: #REF!
Name ___INDEX_SHEET___ASAP_Utilities: #REF!
Name ___INDEX_SHEET___ASAP_Utilities: #REF!
Name __Tab1: #REF!
Name __Tab100: '[1]Port Layout-PA'!$A$1
Name __Tab16: #REF!
Name __Tab17: #REF!
Name __Tab18: #REF!
Name __Tab19: #REF!
Name __Tab20: #REF!
Name __Tab21: #REF!
Name __Tab22: #REF!
Name __Tab23: #REF!
Name __Tab24: #REF!
Name __Tab25: #REF!
Name __Tab26: #REF!
Name __Tab27: #REF!
Name __Tab28: #REF!
Name _dns1: #REF!
Name _dns1: #REF!
Name _dns1: #REF!
Name _dns1: #REF!
Name _dns1: #REF!
Name _dns11: #REF!
Name _dns2: #REF!
Name _Tab1: #REF!
Name _Tab1: #REF!
Name _Tab100: '[2]Port Layout-PA'!$A$1
Name _Tab15: #REF!
Name _Tab15: #REF!
Name _Tab16: #REF!
Name _Tab16: #REF!
Name _Tab17: #REF!
Name _Tab17: #REF!
Name _Tab18: #REF!
Name _Tab19: #REF!
Name _Tab20: #REF!
Name _Tab21: #REF!
Name _Tab22: #REF!
Name _Tab23: #REF!
Name _Tab24: #REF!
Name _Tab25: #REF!
Name _Tab26: #REF!
Name _Tab27: #REF!
Name _Tab28: #REF!
Name _Tab30: #REF!
Name _Tab31: #REF!
Name _xlfn_COUNTIFS: #N/A
Name a: 0.6266
Name aaa: #REF!
Name abc: #REF!
Name ABS_NAME: [3]WWNs!$A$2:$Q$2
Name Activity: [4]Lookup!$F$2:$F$4
Name ADDMSelectList: '[5]Data Validation'!$J$2:$J$5
Name adsfa: #REF!
Name Alias_WWN: '[6]Alias-WWN'!$A$1:$B$65536
Name Amort_Flag: [7]CONTROLS!$B$66
Name app_types: '[8]Core Banking Services'!$L$2:$L$4
Name APPENDIX_10._Reuters_EXTRANET_Failover: #REF!

Sheet TOC

Sheet Hour by Hour(Wave 00B)
A1: Hour by Hour Tasks
A3: Task ID | B3: Environment (CMO/FMO) | C3: Migration tasks | D3: Applications | E3: Servers | F3: Owner Group | G3: Owner | H3: Status | I3: Planned Start Time (ET) | J3: Planned Duration | K3: Planned Finish Time (ET) | L3: Actual Start Time (ET) | M3: Actual Finish Time (ET) | N3: Actual Duration | O3: Comments
A4: 0 | C4: Migration Kickoff Tasks
A5: 0.1 | B5: CMO | C5: Open Command Bridge and Take Role | D5: NA | E5: NA | F5: Migration Lead | G5: Karthik | H5: Pending | I5: 0.3125 | J5: 5 | K5: =I5+(J5/1440) -> 0.31597222
A6: 0.2 | B6: CMO | C6: Ensure Migration Readiness - Final GO/NO-GO | D6: NA | E6: NA | F6: Migration Lead | G6: Karthik | H6: Pending | I6: =K5 -> 0.31597222 | J6: 5 | K6: =I6+(J6/1440) -> 0.31944444
A7: 0.3 | B7: CMO | C7: Confirm Data Replications are completed | D7: NA | E7: NA | F7: Migration Lead | G7: Karthik | H7: Pending | I7: =K6 -> 0.31944444 | J7: 10 | K7: =I7+(J7/1440) -> 0.32638889
A8: 0.4 | B8: CMO | C8: Confirm Backups are completed | D8: NA | E8: NA | F8: Backup Team | G8: TBC | H8: Pending | I8: =K7 -> 0.32638889 | J8: 10 | K8: =I8+(J8/1440) -> 0.33333333
A9: 0.5 | B9: CMO | C9: Confirm T-Minus (T-7 to T-0) are completed | D9: NA | E9: NA | F9: Migration Lead | G9: Karthik | H9: Pending | I9: =K8 -> 0.33333333 | J9: 5 | K9: =I9+(J9/1440) -> 0.33680556
A10: 0.6 | B10: CMO | C10: Disable Alerts | D10: NA | E10: NA | F10: Tools Team | G10: TBC | H10: Pending | I10: =K9 -> 0.33680556 | J10: 10 | K10: =I10+(J10/1440) -> 0.34375
A11: 0.7 | B11: CMO | C11: Disable the Backup | D11: All | E11: All | F11: Backup Team | G11: TBC | H11: Pending | I11: =K10 -> 0.34375 | J11: 15 | K11: =I11+(J11/1440) -> 0.35416667
A12: 1 | C12: Application Shutdown | I12: =K11 -> 0.35416667 | J12: 0 | K12: =I12+(J12/1440) -> 0.35416667
A13: 1.1 | B13: CMO | C13: Complete Application Shutdown Tasks | D13: All | E13: All | F13: Application Team | G13: Refer to App Contacts | H13: Pending | I13: =K12 -> 0.35416667 | J13: 30 | K13: =I13+(J13/1440) -> 0.375
A14: 1.2 | B14: CMO | C14: Complete Database Shutdown Tasks | D14: All | E14: All | F14: DB Team/App Team | G14: TBC | H14: Pending | I14: =K13 -> 0.375 | J14: 30 | K14: =I14+(J14/1440) -> 0.39583333
A15: 1.3 | B15: CMO | C15: Stop the services (various applications) and put them manual startup/Disable mode | D15: All | E15: All | F15: Application Team | G15: Refer to App Contacts | H15: Pending | I15: =K14 -> 0.39583333 | J15: 15 | K15: =I15+(J15/1440) -> 0.40625
A16: 1.4 | B16: CMO | C16: Verify that all application/database/service shutdown tasks have been completed | D16: All | E16: All | F16: Migration Lead | G16: Karthik | H16: Pending | I16: =K15 -> 0.40625 | J16: 15 | K16: =I16+(J16/1440) -> 0.41666667
A17: 2 | C17: Server Shutdown | I17: =K16 -> 0.41666667 | J17: 0 | K17: =I17+(J17/1440) -> 0.41666667
A18: 2.1 | B18: CMO | C18: Shutdown the VMs - CMO | D18: All | E18: All | F18: Migration Team | G18: Manjunath | H18: Pending | I18: =K17 -> 0.41666667 | J18: 30 | K18: =I18+(J18/1440) -> 0.4375
A19: 2.2 | B19: CMO | C19: Ensure that there is no activity on the VMs in CMO | D19: All | E19: All | F19: Migration Team | G19: Manjunath | H19: Pending | I19: =K18 -> 0.4375 | J19: 10 | K19: =I19+(J19/1440) -> 0.44444444
A20: 2.3 | B20: CMO | C20: Verify that the consistency group is in Active (sync) state between CMO & FMO | D20: All | E20: All | F20: Migration Team | G20: Manjunath | H20: Pending | I20: =K19 -> 0.44444444 | J20: 20 | K20: =I20+(J20/1440) -> 0.45833333
A21: 3 | C21: VM Cutover | I21: =K20 -> 0.45833333 | J21: 0 | K21: =I21+(J21/1440) -> 0.45833333
A22: 3.2 | B22: CMO | C22: Enable Image Access on the CG | D22: All | E22: All | F22: Migration Team | G22: Manjunath | H22: Pending | I22: =K21 -> 0.45833333 | J22: 30 | K22: =I22+(J22/1440) -> 0.47916667
A23: 3.3 | B23: FMO | C23: Power On the VMs of the CG at the FMO | D23: All | E23: All | F23: Migration Team | G23: Manjunath | H23: Pending | I23: =K22 -> 0.47916667 | J23: 15 | K23: =I23+(J23/1440) -> 0.48958333
A24: 3.4 | B24: FMO | C24: Update internal/external DNS / LB entries as required(If Applicable) | D24: All | E24: All | F24: Migration Team | G24: Manjunath/DNS | H24: Pending | I24: =K23 -> 0.48958333 | J24: 0 | K24: =I24+(J24/1440) -> 0.48958333
A25: 3.5 | B25: FMO | C25: Perform any remediation required(If Applicable) | D25: All | E25: All | F25: Migration Team | G25: Manjunath | H25: Pending | I25: =K24 -> 0.48958333 | J25: 0 | K25: =I25+(J25/1440) -> 0.48958333
A26: 3.6 | B26: FMO | C26: Perform server boot healthcheck on VMs | D26: All | E26: All | F26: Migration Team | G26: Manjunath | H26: Pending | I26: =K25 -> 0.48958333 | J26: 30 | K26: =I26+(J26/1440) -> 0.51041667
A27: 3.7 | B27: FMO | C27: Release to OS team for validation | D27: All | E27: All | F27: Migration Team | G27: Manjunath | H27: Pending | I27: =K26 -> 0.51041667 | J27: 15 | K27: =I27+(J27/1440) -> 0.52083333
A28: 3.8 | B28: FMO | C28: Validate server tooling | D28: All | E28: All | F28: Migration Team | G28: Karthik | H28: Pending | I28: =K27 -> 0.52083333 | J28: 15 | K28: =I28+(J28/1440) -> 0.53125
A29: 3.9 | B29: FMO | C29: Handover Server for User Acceptance Testing | D29: All | E29: All | F29: Migration Team | G29: Karthik | H29: Pending | I29: =K28 -> 0.53125 | J29: 10 | K29: =I29+(J29/1440) -> 0.53819444
A30: 4 | C30: Application Startup | I30: =K29 -> 0.53819444 | J30: 0 | K30: =I30+(J30/1440) -> 0.53819444
A31: 4.1 | B31: FMO | C31: Complete Database Startup Tasks | D31: All | E31: All | F31: DB Team/App Team | G31: TBC/Refer to App Contacts | H31: Pending | I31: =K30 -> 0.53819444 | J31: 30 | K31: =I31+(J31/1440) -> 0.55902778
A32: 4.2 | B32: FMO | C32: Start the services (various applications) and put them automatic startup mode as required | D32: All | E32: All | F32: Application Team | G32: Refer to App Contacts | H32: Pending | I32: =K31 -> 0.55902778 | J32: 15 | K32: =I32+(J32/1440) -> 0.56944444 | O32: Service Now is good with Duration
A33: 4.3 | B33: FMO | C33: Complete Application Startup Tasks | D33: All | E33: All | F33: Application Team | G33: Refer to App Contacts | H33: Pending | I33: =K32 -> 0.56944444 | J33: 30 | K33: =I33+(J33/1440) -> 0.59027778
A34: 4.4 | B34: FMO | C34: Validate all application startup tasks are complete | D34: All | E34: All | F34: Migration Lead | G34: Karthik | H34: Pending | I34: =K33 -> 0.59027778 | J34: 10 | K34: =I34+(J34/1440) -> 0.59722222
A35: 5 | C35: Application Testing / Migration completion | I35: =K34 -> 0.59722222 | J35: 0 | K35: =I35+(J35/1440) -> 0.59722222
A36: 5.1 | B36: FMO | C36: Complete Operational Application Testing per UAT Document | D36: All | E36: All | F36: Application Team | G36: Refer to App Contacts | H36: Pending | I36: =K35 -> 0.59722222 | J36: 165 | K36: =I36+(J36/1440) -> 0.71180556 | O36: Filenet 2.45hrs
A37: 5.2 | B37: FMO | C37: Validate all application testing completed successfully | D37: All | E37: All | F37: Migration Lead | G37: Karthik | H37: Pending | I37: =K36 -> 0.71180556 | J37: 15 | K37: =I37+(J37/1440) -> 0.72222222
A38: 5.3 | B38: FMO | C38: Enable Direct access on the Consistency Group at FMO | D38: All | E38: All | F38: Migration Team | G38: Manjunath | H38: Pending | I38: =K37 -> 0.72222222 | J38: 10 | K38: =I38+(J38/1440) -> 0.72916667
A39: 5.4 | B39: FMO | C39: Cleanup the Consistency Group in RP4VM | D39: All | E39: All | F39: Migration Team | G39: Manjunath | H39: Pending | I39: =K38 -> 0.72916667 | J39: 5 | K39: =I39+(J39/1440) -> 0.73263889
A40: 5.5 | B40: FMO | C40: Complete Application Testing (Business Testing) | F40: Application Team | G40: Refer to App Contacts | H40: Pending | I40: =K39 -> 0.73263889 | J40: 30 | K40: =I40+(J40/1440) -> 0.75347222 | L40: ESB to confir(Abhishek) | O40: No Business testing for CLB Filenet
A41: 5.6 | B41: FMO | C41: Migration Complete Sign Off | D41: All | E41: All | F41: Migration Team | G41: Hemang/Mike | H41: Pending | I41: =K40 -> 0.75347222 | J41: 5 | K41: =I41+(J41/1440) -> 0.75694444
...

Sheet Tracker Sheet
A1: OVERALL STATUS % | D1: =AVERAGE(F19:F143) -> 60.763889 | F1: Do Not Migrate (DNM) % | H1: =COUNTIF(H19:H913, "DNM")/(COUNTA(H19:H913)-COUNTIF(H19:H913,"N/A")) -> 0 | I1: =COUNTIF(I19:I913, "DNM")/(COUNTA(I19:I913)-COUNTIF(I19:I913,"N/A")) -> 0 | J1: =COUNTIF(J19:J913, "DNM")/(COUNTA(J19:J913)-COUNTIF(J19:J913,"N/A")) -> 0 | K1: =COUNTIF(K19:K913, "DNM")/(COUNTA(K19:K913)-COUNTIF(K19:K913,"N/A")) -> 0 | L1: =COUNTIF(L19:L913, "DNM")/(COUNTA(L19:L913)-COUNTIF(L19:L913,"N/A")) -> 0 | M1: =COUNTIF(M19:M913, "DNM")/(COUNTA(M19:M913)-COUNTIF(M19:M913,"N/A")) -> 0 | N1: =COUNTIF(N19:N913, "DNM")/(COUNTA(N19:N913)-COUNTIF(N19:N913,"N/A")) -> 0 | O1: =COUNTIF(O19:O913, "DNM")/(COUNTA(O19:O913)-COUNTIF(O19:O913,"N/A")) -> 0 | ... AM1: =COUNTIF(AM19:AM913, "DNM")/(COUNTA(AM19:AM913)-COUNTIF(AM19:AM913,"N/A")) -> 0
F2: Pending (By VM %) | H2: =COUNTIF(H19:H913, "Pending")/(COUNTA(H19:H913)-COUNTIF(H19:H913,"N/A")) -> 0 | I2: =COUNTIF(I19:I913, "Pending")/(COUNTA(I19:I913)-COUNTIF(I19:I913,"N/A")) -> 0 | J2: =COUNTIF(J19:J913, "Pending")/(COUNTA(J19:J913)-COUNTIF(J19:J913,"N/A")) -> 0.44444444 | K2: =COUNTIF(K19:K913, "Pending")/(COUNTA(K19:K913)-COUNTIF(K19:K913,"N/A")) -> 0 | L2: =COUNTIF(L19:L913, "Pending")/(COUNTA(L19:L913)-COUNTIF(L19:L913,"N/A")) -> 0 | M2: =COUNTIF(M19:M913, "Pending")/(COUNTA(M19:M913)-COUNTIF(M19:M913,"N/A")) -> 0 | N2: =COUNTIF(N19:N913, "Pending")/(COUNTA(N19:N913)-COUNTIF(N19:N913,"N/A")) -> 0 | O2: =COUNTIF(O19:O913, "Pending")/(COUNTA(O19:O913)-COUNTIF(O19:O913,"N/A")) -> 0 | ... AM2: =COUNTIF(AM19:AM913, "Pending")/(COUNTA(AM19:AM913)-COUNTIF(AM19:AM913,"N/A")) -> 1
F3: In-Progress (By VM %) | H3: =COUNTIF(H19:H913, "In-Progress")/(COUNTA(H19:H913)-COUNTIF(H19:H913,"N/A")) -> 0 | I3: =COUNTIF(I19:I913, "In-Progress")/(COUNTA(I19:I913)-COUNTIF(I19:I913,"N/A")) -> 0.77777778 | J3: =COUNTIF(J19:J913, "In-Progress")/(COUNTA(J19:J913)-COUNTIF(J19:J913,"N/A")) -> 0.33333333 | K3: =COUNTIF(K19:K913, "In-Progress")/(COUNTA(K19:K913)-COUNTIF(K19:K913,"N/A")) -> 0.33333333 | L3: =COUNTIF(L19:L913, "In-Progress")/(COUNTA(L19:L913)-COUNTIF(L19:L913,"N/A")) -> 0.33333333 | M3: =COUNTIF(M19:M913, "In-Progress")/(COUNTA(M19:M913)-COUNTIF(M19:M913,"N/A")) -> 0.33333333 | N3: =COUNTIF(N19:N913, "In-Progress")/(COUNTA(N19:N913)-COUNTIF(N19:N913,"N/A")) -> 0.33333333 | O3: =COUNTIF(O19:O913, "In-Progress")/(COUNTA(O19:O913)-COUNTIF(O19:O913,"N/A")) -> 0.33333333 | ... AM3: =COUNTIF(AM19:AM913, "In-Progress")/(COUNTA(AM19:AM913)-COUNTIF(AM19:AM913,"N/A")) -> 0
A4: Migration Kickoff Tasks | D4: =AVERAGE(H4:N4) -> 0.58730159 | F4: Complete (By VM %) | H4: =COUNTIF(H19:H1001,"Complete")/COUNTA(H19:H1001)+COUNTIF(H19:H1001,"DNM")/COUNTA(H19:H1001)+COUNTIF(H19:H1001,"NA")/COUNTA(H19:H1001) -> 1 | I4: =COUNTIF(I19:I1001,"Complete")/COUNTA(I19:I1001)+COUNTIF(I19:I1001,"DNM")/COUNTA(I19:I1001)+COUNTIF(I19:I1001,"NA")/COUNTA(I19:I1001) -> 0.22222222 | J4: =COUNTIF(J19:J1001,"Complete")/COUNTA(J19:J1001)+COUNTIF(J19:J1001,"DNM")/COUNTA(J19:J1001)+COUNTIF(J19:J1001,"NA")/COUNTA(J19:J1001) -> 0.22222222 | K4: =COUNTIF(K19:K1001,"Complete")/COUNTA(K19:K1001)+COUNTIF(K19:K1001,"DNM")/COUNTA(K19:K1001)+COUNTIF(K19:K1001,"NA")/COUNTA(K19:K1001) -> 0.66666667 | L4: =COUNTIF(L19:L1001,"Complete")/COUNTA(L19:L1001)+COUNTIF(L19:L1001,"DNM")/COUNTA(L19:L1001)+COUNTIF(L19:L1001,"NA")/COUNTA(L19:L1001) -> 0.66666667 | M4: =COUNTIF(M19:M1001,"Complete")/COUNTA(M19:M1001)+COUNTIF(M19:M1001,"DNM")/COUNTA(M19:M1001)+COUNTIF(M19:M1001,"NA")/COUNTA(M19:M1001) -> 0.66666667 | N4: =COUNTIF(N19:N1001,"Complete")/COUNTA(N19:N1001)+COUNTIF(N19:N1001,"DNM")/COUNTA(N19:N1001)+COUNTIF(N19:N1001,"NA")/COUNTA(N19:N1001) -> 0.66666667 | O4: =COUNTIF(O19:O1001,"Complete")/COUNTA(O19:O1001)+COUNTIF(O19:O1001,"DNM")/COUNTA(O19:O1001)+COUNTIF(O19:O1001,"NA")/COUNTA(O19:O1001) -> 0.66666667 | ... AM4: =COUNTIF(AM19:AM1001,"Complete")/COUNTA(AM19:AM1001)+COUNTIF(AM19:AM1001,"DNM")/COUNTA(AM19:AM1001)+COUNTIF(AM19:AM1001,"NA")/COUNTA(AM19:AM1001) -> 0
A5: Application Shutdown | D5: =AVERAGE(O4:R4) -> 0.75 | F5: Do Not Migrate (DNM) | H5: =H9*H1 -> 0 | I5: =I9*I1 -> 0 | J5: =J9*J1 -> 0 | K5: =K9*K1 -> 0 | L5: =L9*L1 -> 0 | M5: =M9*M1 -> 0 | N5: =N9*N1 -> 0 | O5: =O9*O1 -> 0 | ... AM5: =AM9*AM1 -> 0
A6: Server Shutdown | D6: =AVERAGE(S4:U4) -> 0.66666667 | F6: Pending (By VM Count) | H6: =H9*H2 -> 0 | I6: =I9*I2 -> 0 | J6: =J9*J2 -> 4 | K6: =K9*K2 -> 0 | L6: =L9*L2 -> 0 | M6: =M9*M2 -> 0 | N6: =N9*N2 -> 0 | O6: =O9*O2 -> 0 | ... AM6: =AM9*AM2 -> 9
A7: VM Cutover | D7: =AVERAGE(V4:AC4) -> 0.70833333 | F7: In-Progress (By VM Count) | H7: =H9*H3 -> 0 | I7: =I9*I3 -> 7 | J7: =J9*J3 -> 3 | K7: =K9*K3 -> 3 | L7: =L9*L3 -> 3 | M7: =M9*M3 -> 3 | N7: =N9*N3 -> 3 | O7: =O9*O3 -> 3 | ... AM7: =AM9*AM3 -> 0
A8: Application Startup | D8: =AVERAGE(AD4:AG4) -> 0.66666667 | F8: Complete (By VM Count) | H8: =H9*H4 -> 9 | I8: =I9*I4 -> 2 | J8: =J9*J4 -> 2 | K8: =K9*K4 -> 6 | L8: =L9*L4 -> 6 | M8: =M9*M4 -> 6 | N8: =N9*N4 -> 6 | O8: =O9*O4 -> 6 | ... AM8: =AM9*AM4 -> 0
A9: Application Testing / Migration completion | D9: =AVERAGE(AH4:AM4) -> 0.33333333 | F9: Total VM Count | H9: =COUNTA($A$19:$A$992) -> 9 | I9: =COUNTA($A$19:$A$123) -> 9 | J9: =COUNTA($A$19:$A$123) -> 9 | K9: =COUNTA($A$19:$A$123) -> 9 | L9: =COUNTA($A$19:$A$123) -> 9 | M9: =COUNTA($A$19:$A$123) -> 9 | N9: =COUNTA($A$19:$A$123) -> 9 | O9: =COUNTA($A$19:$A$123) -> 9 | P9: =COUNTA($A$19:$A$123) -> 9 | ... AM9: =COUNTA($A$19:$A$123) -> 9
A11: Issue Tracker: | F11: Planned Duration | H11: 5 | I11: 5 | J11: 10 | K11: 10 | L11: 5 | M11: 10 | N11: 15 | O11: 30 | P11: 30 | Q11: 15 | R11: 15 | S11: 30 | T11: 10 | U11: 20 | V11: 30 | W11: 15 | X11: 0 | Y11: 0 | Z11: 30 | AA11: 15 | AB11: 15 | AC11: 10 | AD11: 30 | AE11: 15 | AF11: 30 | AG11: 10 | AH11: 165 | AI11: 15 | AJ11: 10 | AK11: 5 | AL11: 30 | AM11: 5
A12: Number of Open Issues | D12: =COUNTIF(#REF!,"Open") -> #REF! | F12: Planned Start Time | H12: 0.3125 | I12: =H13 -> 0.31597222 | J12: =I13 -> 0.31944444 | K12: =J13 -> 0.32638889 | L12: =K13 -> 0.33333333 | M12: =L13 -> 0.33680556 | N12: =M13 -> 0.34375 | O12: =N13 -> 0.35416667 | P12: =O13 -> 0.375 | ... AM12: =AL13 -> 0.75347222
A13: Number of Closed Issues | D13: =COUNTIF(#REF!,"Closed") -> #REF! | F13: Planned End Time | H13: =H12+(H11/1440) -> 0.31597222 | I13: =I12+(I11/1440) -> 0.31944444 | J13: =J12+(J11/1440) -> 0.32638889 | K13: =K12+(K11/1440) -> 0.33333333 | L13: =L12+(L11/1440) -> 0.33680556 | M13: =M12+(M11/1440) -> 0.34375 | N13: =N12+(N11/1440) -> 0.35416667 | O13: =O12+(O11/1440) -> 0.375 | ... AM13: =AM12+(AM11/1440) -> 0.75694444
A14: Total Number of Issues Logged | D14: =D12+D13 -> #REF! | F14: Actual Start Time | H14: ST | O14: ST | S14: ST | V14: ST | AD14: ST | AH14: ST
F15: Actual End Time | N15: ET | R15: ET | U15: ET | AC15: ET | AG15: ET | AM15: ET
F16: Resource Performing Task | H16: xxxx | I16: xxxx | J16: xxxx | K16: TBC | L16: xxxx | M16: TBC | N16: TBC | O16: Refer to App Contacts | P16: TBC | Q16: Refer to App Contacts | R16: xxxx | S16: xxxx | T16: xxxx | U16: xxxx | V16: xxxx | W16: xxxx | X16: xxxx/DNS | Y16: xxxx | Z16: xxxx | AA16: xxxx | AB16: xxxx | AC16: xxxx | AD16: TBC/Refer to App Contacts | AE16: Refer to App Contacts | AF16: Refer to App Contacts | AG16: xxxx | AH16: Refer to App Contacts | AI16: xxxx | AJ16: xxxx | AK16: xxxx | AL16: Refer to App Contacts | AM16: xxxx/xxxx
H17: Migration Kickoff Tasks | O17: Application Shutdown | S17: Server Shutdown | V17: VM Cutover | AD17: Application Startup | AH17: Application Testing / Migration completion
A18: VM | B18: Function/Role | C18: Move Group | D18: Sequence | E18: OS | F18: VM Migration % Complete | H18: Open Command Bridge and Take Role | I18: Ensure Migration Readiness - Final GO/NO-GO | J18: Confirm Data Replications are completed | K18: Confirm Backups are completed | L18: Confirm T-Minus (T-7 to T-0) are completed | M18: Disable Alerts | N18: Disable the Backup | O18: Application Shutdown Tasks | P18: Database Shutdown Tasks | Q18: Stop the services (various applications) and put them manual startup/Disable mode | R18: Verify that all application/database/service shutdown tasks have been completed | S18: Shutdown the VMs - CMO | T18: Ensure that there is no activity on the VMs in CMO | U18: Verify that the consistency group is in Active (sync) state between CMO & FMO | V18: Enable Image Access on the CG | W18: Power On the VMs of the CG at the FMO | X18: Update internal/external DNS / LB entries as required (If Applicable) | Y18: Perform any remediation required(If Applicable) | Z18: Perform server boot healthcheck on VMs | AA18: Release to OS team for validation | AB18: Validate server tooling | AC18: Handover Server for User Acceptance Testing | AD18: Complete Database Startup Tasks | AE18: Start the services (various applications) and put them automatic startup mode as required | AF18: Complete Application Startup Tasks | AG18: Validate all application startup tasks are complete | AH18: Complete Operational Application Testing per UAT Document | AI18: Validate all application testing completed successfully | AJ18: Enable Direct access on the Consistency Group at FMO | AK18: Cleanup the Consistency Group in RP4VM | AL18: Complete Application Testing (Business Testing) | AM18: Migration Complete Sign Off
A19: Server01 | B19: DB | C19: Wave 00A | D19: None | E19: Windows | F19: =(COUNTIF(H19:AM19,"Complete")/COUNTA(H19:AM19)+COUNTIF(H19:AM19,"DNM")/COUNTA(H19:AM19)+COUNTIF(H19:AM19,"NA")/COUNTA(H19:AM19))*100 -> 90.625 | H19: Complete | I19: Complete | J19: Complete | K19: Complete | L19: Complete | M19: Complete | N19: Complete | O19: Complete | P19: Complete | Q19: Complete | R19: Complete | S19: Complete | T19: Complete | U19: Complete | V19: Complete | W19: Complete | X19: Complete | Y19: Complete | Z19: Complete | AA19: Complete | AB19: Complete | AC19: Complete | AD19: Complete | AE19: Complete | AF19: Complete | AG19: Complete | AH19: Complete | AI19: Complete | AJ19: Complete | AK19: Pending | AL19: Pending | AM19: Pending
A20: Server02 | B20: App | C20: Wave 00A | D20: None | E20: Windows | F20: =(COUNTIF(H20:AM20,"Complete")/COUNTA(H20:AM20)+COUNTIF(H20:AM20,"DNM")/COUNTA(H20:AM20)+COUNTIF(H20:AM20,"NA")/COUNTA(H20:AM20))*100 -> 90.625 | H20: Complete | I20: Complete | J20: Complete | K20: Complete | L20: Complete | M20: Complete | N20: Complete | O20: Complete | P20: Complete | Q20: Complete | R20: Complete | S20: Complete | T20: Complete | U20: Complete | V20: Complete | W20: Complete | X20: Complete | Y20: Complete | Z20: Complete | AA20: Complete | AB20: Complete | AC20: Complete | AD20: Complete | AE20: Complete | AF20: Complete | AG20: Complete | AH20: Complete | AI20: Complete | AJ20: Complete | AK20: Pending | AL20: Pending | AM20: Pending
A21: Server03 | B21: App | C21: Wave 00A | D21: None | E21: Windows | F21: =(COUNTIF(H21:AM21,"Complete")/COUNTA(H21:AM21)+COUNTIF(H21:AM21,"DNM")/COUNTA(H21:AM21)+COUNTIF(H21:AM21,"NA")/COUNTA(H21:AM21))*100 -> 9.375 | H21: Complete | I21: In-Progress | J21: In-Progress | K21: In-Progress | L21: In-Progress | M21: In-Progress | N21: In-Progress | O21: In-Progress | P21: Complete | Q21: In-Progress | R21: In-Progress | S21: In-Progress | T21: In-Progress | U21: In-Progress | V21: Complete | W21: In-Progress | X21: In-Progress | Y21: In-Progress | Z21: In-Progress | AA21: In-Progress | AB21: In-Progress | AC21: In-Progress | AD21: In-Progress | AE21: In-Progress | AF21: In-Progress | AG21: In-Progress | AH21: In-Progress | AI21: In-Progress | AJ21: In-Progress | AK21: Pending | AL21: Pending | AM21: Pending
A22: Server04 | B22: App | C22: Wave 00A | D22: None | E22: Windows | F22: =(COUNTIF(H22:AM22,"Complete")/COUNTA(H22:AM22)+COUNTIF(H22:AM22,"DNM")/COUNTA(H22:AM22)+COUNTIF(H22:AM22,"NA")/COUNTA(H22:AM22))*100 -> 9.375 | H22: Complete | I22: In-Progress | J22: In-Progress | K22: In-Progress | L22: In-Progress | M22: In-Progress | N22: In-Progress | O22: In-Progress | P22: Complete | Q22: In-Progress | R22: In-Progress | S22: In-Progress | T22: In-Progress | U22: In-Progress | V22: Complete | W22: In-Progress | X22: In-Progress | Y22: In-Progress | Z22: In-Progress | AA22: In-Progress | AB22: In-Progress | AC22: In-Progress | AD22: In-Progress | AE22: In-Progress | AF22: In-Progress | AG22: In-Progress | AH22: In-Progress | AI22: In-Progress | AJ22: In-Progress | AK22: Pending | AL22: Pending | AM22: Pending
A23: Server05 | B23: App | C23: Wave 00A | D23: None | E23: Windows | F23: =(COUNTIF(H23:AM23,"Complete")/COUNTA(H23:AM23)+COUNTIF(H23:AM23,"DNM")/COUNTA(H23:AM23)+COUNTIF(H23:AM23,"NA")/COUNTA(H23:AM23))*100 -> 9.375 | H23: Complete | I23: In-Progress | J23: In-Progress | K23: In-Progress | L23: In-Progress | M23: In-Progress | N23: In-Progress | O23: In-Progress | P23: Complete | Q23: In-Progress | R23: In-Progress | S23: In-Progress | T23: In-Progress | U23: In-Progress | V23: Complete | W23: In-Progress | X23: In-Progress | Y23: In-Progress | Z23: In-Progress | AA23: In-Progress | AB23: In-Progress | AC23: In-Progress | AD23: In-Progress | AE23: In-Progress | AF23: In-Progress | AG23: In-Progress | AH23: In-Progress | AI23: In-Progress | AJ23: In-Progress | AK23: Pending | AL23: Pending | AM23: Pending
A24: Server06 | B24: App | C24: Wave 00A | D24: None | E24: Windows | F24: =(COUNTIF(H24:AM24,"Complete")/COUNTA(H24:AM24)+COUNTIF(H24:AM24,"DNM")/COUNTA(H24:AM24)+COUNTIF(H24:AM24,"NA")/COUNTA(H24:AM24))*100 -> 84.375 | H24: Complete | I24: In-Progress | J24: Pending | K24: Complete | L24: Complete | M24: Complete | N24: Complete | O24: Complete | P24: Complete | Q24: Complete | R24: Complete | S24: Complete | T24: Complete | U24: Complete | V24: Complete | W24: Complete | X24: Complete | Y24: Complete | Z24: Complete | AA24: Complete | AB24: Complete | AC24: Complete | AD24: Complete | AE24: Complete | AF24: Complete | AG24: Complete | AH24: Complete | AI24: Complete | AJ24: Complete | AK24: Pending | AL24: Pending | AM24: Pending
A25: Server07 | B25: App | C25: Wave 00A | D25: None | E25: Windows | F25: =(COUNTIF(H25:AM25,"Complete")/COUNTA(H25:AM25)+COUNTIF(H25:AM25,"DNM")/COUNTA(H25:AM25)+COUNTIF(H25:AM25,"NA")/COUNTA(H25:AM25))*100 -> 84.375 | H25: Complete | I25: In-Progress | J25: Pending | K25: Complete | L25: Complete | M25: Complete | N25: Complete | O25: Complete | P25: Complete | Q25: Complete | R25: Complete | S25: Complete | T25: Complete | U25: Complete | V25: Complete | W25: Complete | X25: Complete | Y25: Complete | Z25: Complete | AA25: Complete | AB25: Complete | AC25: Complete | AD25: Complete | AE25: Complete | AF25: Complete | AG25: Complete | AH25: Complete | AI25: Complete | AJ25: Complete | AK25: Pending | AL25: Pending | AM25: Pending
A26: Server08 | B26: App | C26: Wave 00A | D26: None | E26: Windows | F26: =(COUNTIF(H26:AM26,"Complete")/COUNTA(H26:AM26)+COUNTIF(H26:AM26,"DNM")/COUNTA(H26:AM26)+COUNTIF(H26:AM26,"NA")/COUNTA(H26:AM26))*100 -> 84.375 | H26: Complete | I26: In-Progress | J26: Pending | K26: Complete | L26: Complete | M26: Complete | N26: Complete | O26: Complete | P26: Complete | Q26: Complete | R26: Complete | S26: Complete | T26: Complete | U26: Complete | V26: Complete | W26: Complete | X26: Complete | Y26: Complete | Z26: Complete | AA26: Complete | AB26: Complete | AC26: Complete | AD26: Complete | AE26: Complete | AF26: Complete | AG26: Complete | AH26: Complete | AI26: Complete | AJ26: Complete | AK26: Pending | AL26: Pending | AM26: Pending
A27: Server09 | B27: App | C27: Wave 00A | D27: None | E27: Windows | F27: =(COUNTIF(H27:AM27,"Complete")/COUNTA(H27:AM27)+COUNTIF(H27:AM27,"DNM")/COUNTA(H27:AM27)+COUNTIF(H27:AM27,"NA")/COUNTA(H27:AM27))*100 -> 84.375 | H27: Complete | I27: In-Progress | J27: Pending | K27: Complete | L27: Complete | M27: Complete | N27: Complete | O27: Complete | P27: Complete | Q27: Complete | R27: Complete | S27: Complete | T27: Complete | U27: Complete | V27: Complete | W27: Complete | X27: Complete | Y27: Complete | Z27: Complete | AA27: Complete | AB27: Complete | AC27: Complete | AD27: Complete | AE27: Complete | AF27: Complete | AG27: Complete | AH27: Complete | AI27: Complete | AJ27: Complete | AK27: Pending | AL27: Pending | AM27: Pending

Sheet Email Status Template Wave 00A
A1: Migration Communication Tracker | Q1: Color Code
A2: Note: | Q2: On Track
A3: Migration Command Center Bridge will be open during the complete cutover window | Q3: Complete
A4: Status Report to be shared via email every 1 hour | Q4: Issue/Delay
A5: If there are any issues/delays - The status frequency will be every hour or when there is an update, until the issue is fully resolved | Q5: Delayed
A6: Migration Name: | B6: Migrate XX ABC Crop VM's currently existing in CMO Z1 to FMO Z2 | Q6: Major Issue/Roll Back
A7: Migration Status: | B7: Not Started
A8: Potential Delay | B8: NO
A9: RISK of Executing Backout Plan | B9: NO
A10: RISK of Exceeding Outage Window | B10: NO
A11: Migration Comment:
A12: Migration Lead/Project Manager: | B12: xxxx
A13: Next Status Update | B13: N/A
A14: Runbook Link:
A15: Next Steps:
A17: Planned Outage Window | B17: DD/MM/YYYY 08:00 EST | C17: DD/MM/YYYY 20:00 EST | F17: ON TRACK
A19: Key Milestone Tracking | B19: Planned Start Time | C19: Planned End Time | D19: Actual Start Time | E19: Actual End Time | F19: Status | G19: Comments
A20: Migration Kickoff Tasks | D20: ='Tracker Sheet'!H14 -> ST | E20: ='Tracker Sheet'!N15 -> ET | F20: ON TRACK
A21: Application Shutdown | D21: ='Tracker Sheet'!O14 -> ST | E21: ='Tracker Sheet'!R15 -> ET | F21: ON TRACK
A22: Server Shutdown | D22: ='Tracker Sheet'!S14 -> ST | E22: ='Tracker Sheet'!U15 -> ET | F22: ON TRACK
A23: VM Cutover | D23: ='Tracker Sheet'!V14 -> ST | E23: ='Tracker Sheet'!AC15 -> ET | F23: ON TRACK
A24: Application Startup | D24: ='Tracker Sheet'!AD14 -> ST | E24: ='Tracker Sheet'!AG15 -> ET | F24: ON TRACK
A25: Application Testing | D25: ='Tracker Sheet'!AH14 -> ST | E25: ='Tracker Sheet'!AM15 -> ET | F25: ON TRACK
AL33: =R15 -> 0
R42: Migration Kickoff Tasks | W42: ='Tracker Sheet'!D4 -> 0.58730159 | AA42: Number of Open Issues | AD42: ='Tracker Sheet'!D12 -> #REF! | AI42: Pending (By VM %) | AJ42: =AVERAGE('Tracker Sheet'!H2:AM2) -> 0.10763889
R43: Application Shutdown | W43: ='Tracker Sheet'!D5 -> 0.75 | AA43: Number of Closed Issues | AD43: ='Tracker Sheet'!D13 -> #REF! | AI43: In-Progress (By VM %) | AJ43: =AVERAGE('Tracker Sheet'!H3:AM3) -> 0.28472222
R44: Server Shutdown | W44: ='Tracker Sheet'!D6 -> 0.66666667 | AA44: Total Number of Issues Logged | AD44: ='Tracker Sheet'!D14 -> #REF! | AI44: Complete (By VM %) | AJ44: =AVERAGE('Tracker Sheet'!H4:AM4) -> 0.60763889
R45: VM Cutover | W45: ='Tracker Sheet'!D7 -> 0.70833333
R46: Application Startup | W46: ='Tracker Sheet'!D8 -> 0.66666667
R47: Application Testing / Migration completion | W47: ='Tracker Sheet'!D9 -> 0.33333333

Sheet Tracker Sheet(Wave 00B)
A1: OVERALL STATUS % | F1: Do Not Migrate (DNM) % | H1: =COUNTIF(H12:H910, "DNM")/(COUNTA(H12:H910)-COUNTIF(H12:H910,"N/A")) -> 0 | I1: =COUNTIF(I12:I910, "DNM")/(COUNTA(I12:I910)-COUNTIF(I12:I910,"N/A")) -> 0 | J1: =COUNTIF(J12:J910, "DNM")/(COUNTA(J12:J910)-COUNTIF(J12:J910,"N/A")) -> 0 | K1: =COUNTIF(K12:K910, "DNM")/(COUNTA(K12:K910)-COUNTIF(K12:K910,"N/A")) -> 0 | L1: =COUNTIF(L12:L910, "DNM")/(COUNTA(L12:L910)-COUNTIF(L12:L910,"N/A")) -> 0 | M1: =COUNTIF(M12:M910, "DNM")/(COUNTA(M12:M910)-COUNTIF(M12:M910,"N/A")) -> 0 | N1: =COUNTIF(N12:N910, "DNM")/(COUNTA(N12:N910)-COUNTIF(N12:N910,"N/A")) -> 0 | O1: =COUNTIF(O12:O910, "DNM")/(COUNTA(O12:O910)-COUNTIF(O12:O910,"N/A")) -> 0 | ... AM1: =COUNTIF(AM12:AM910, "DNM")/(COUNTA(AM12:AM910)-COUNTIF(AM12:AM910,"N/A")) -> 0
F2: Pending (By VM %) | H2: =COUNTIF(H12:H910, "Pending")/(COUNTA(H12:H910)-COUNTIF(H12:H910,"N/A")) -> 1 | I2: =COUNTIF(I12:I910, "Pending")/(COUNTA(I12:I910)-COUNTIF(I12:I910,"N/A")) -> 1 | J2: =COUNTIF(J12:J910, "Pending")/(COUNTA(J12:J910)-COUNTIF(J12:J910,"N/A")) -> 1 | K2: =COUNTIF(K12:K910, "Pending")/(COUNTA(K12:K910)-COUNTIF(K12:K910,"N/A")) -> 1 | L2: =COUNTIF(L12:L910, "Pending")/(COUNTA(L12:L910)-COUNTIF(L12:L910,"N/A")) -> 1 | M2: =COUNTIF(M12:M910, "Pending")/(COUNTA(M12:M910)-COUNTIF(M12:M910,"N/A")) -> 1 | N2: =COUNTIF(N12:N910, "Pending")/(COUNTA(N12:N910)-COUNTIF(N12:N910,"N/A")) -> 1 | O2: =COUNTIF(O12:O910, "Pending")/(COUNTA(O12:O910)-COUNTIF(O12:O910,"N/A")) -> 1 | ... AM2: =COUNTIF(AM12:AM910, "Pending")/(COUNTA(AM12:AM910)-COUNTIF(AM12:AM910,"N/A")) -> 1
F3: In-Progress (By VM %) | H3: =COUNTIF(H12:H910, "In-Progress")/(COUNTA(H12:H910)-COUNTIF(H12:H910,"N/A")) -> 0 | I3: =COUNTIF(I12:I910, "In-Progress")/(COUNTA(I12:I910)-COUNTIF(I12:I910,"N/A")) -> 0 | J3: =COUNTIF(J12:J910, "In-Progress")/(COUNTA(J12:J910)-COUNTIF(J12:J910,"N/A")) -> 0 | K3: =COUNTIF(K12:K910, "In-Progress")/(COUNTA(K12:K910)-COUNTIF(K12:K910,"N/A")) -> 0 | L3: =COUNTIF(L12:L910, "In-Progress")/(COUNTA(L12:L910)-COUNTIF(L12:L910,"N/A")) -> 0 | M3: =COUNTIF(M12:M910, "In-Progress")/(COUNTA(M12:M910)-COUNTIF(M12:M910,"N/A")) -> 0 | N3: =COUNTIF(N12:N910, "In-Progress")/(COUNTA(N12:N910)-COUNTIF(N12:N910,"N/A")) -> 0 | O3: =COUNTIF(O12:O910, "In-Progress")/(COUNTA(O12:O910)-COUNTIF(O12:O910,"N/A")) -> 0 | ... AM3: =COUNTIF(AM12:AM910, "In-Progress")/(COUNTA(AM12:AM910)-COUNTIF(AM12:AM910,"N/A")) -> 0
F4: Complete (By VM %) | H4: =COUNTIF(H12:H910, "Complete")/(COUNTA(H12:H910)-COUNTIF(H12:H910,"N/A")) -> 0 | I4: =COUNTIF(I12:I910, "Complete")/(COUNTA(I12:I910)-COUNTIF(I12:I910,"N/A")) -> 0 | J4: =COUNTIF(J12:J910, "Complete")/(COUNTA(J12:J910)-COUNTIF(J12:J910,"N/A")) -> 0 | K4: =COUNTIF(K12:K910, "Complete")/(COUNTA(K12:K910)-COUNTIF(K12:K910,"N/A")) -> 0 | L4: =COUNTIF(L12:L910, "Complete")/(COUNTA(L12:L910)-COUNTIF(L12:L910,"N/A")) -> 0 | M4: =COUNTIF(M12:M910, "Complete")/(COUNTA(M12:M910)-COUNTIF(M12:M910,"N/A")) -> 0 | N4: =COUNTIF(N12:N910, "Complete")/(COUNTA(N12:N910)-COUNTIF(N12:N910,"N/A")) -> 0 | O4: =COUNTIF(O12:O910, "Complete")/(COUNTA(O12:O910)-COUNTIF(O12:O910,"N/A")) -> 0 | ... AM4: =COUNTIF(AM12:AM910, "Complete")/(COUNTA(AM12:AM910)-COUNTIF(AM12:AM910,"N/A")) -> 0
F5: Do Not Migrate (DNM) | H5: =H9*H1 -> 0 | I5: =I9*I1 -> 0 | J5: =J9*J1 -> 0 | K5: =K9*K1 -> 0 | L5: =L9*L1 -> 0 | M5: =M9*M1 -> 0 | N5: =N9*N1 -> 0 | O5: =O9*O1 -> 0 | ... AM5: =AM9*AM1 -> 0
A6: =AVERAGE(F12:F140) -> 0 | F6: Pending (By VM Count) | H6: =H9*H2 -> 13 | I6: =I9*I2 -> 13 | J6: =J9*J2 -> 13 | K6: =K9*K2 -> 13 | L6: =L9*L2 -> 13 | M6: =M9*M2 -> 13 | N6: =N9*N2 -> 13 | O6: =O9*O2 -> 13 | ... AM6: =AM9*AM2 -> 13
F7: In-Progress (By VM Count) | H7: =H9*H3 -> 0 | I7: =I9*I3 -> 0 | J7: =J9*J3 -> 0 | K7: =K9*K3 -> 0 | L7: =L9*L3 -> 0 | M7: =M9*M3 -> 0 | N7: =N9*N3 -> 0 | O7: =O9*O3 -> 0 | ... AM7: =AM9*AM3 -> 0
F8: Complete (By VM Count) | H8: =H9*H4 -> 0 | I8: =I9*I4 -> 0 | J8: =J9*J4 -> 0 | K8: =K9*K4 -> 0 | L8: =L9*L4 -> 0 | M8: =M9*M4 -> 0 | N8: =N9*N4 -> 0 | O8: =O9*O4 -> 0 | ... AM8: =AM9*AM4 -> 0
F9: Total VM Count | H9: =COUNTA($A$12:$A$989) -> 13 | I9: =COUNTA($A$12:$A$120) -> 13 | J9: =COUNTA($A$12:$A$120) -> 13 | K9: =COUNTA($A$12:$A$120) -> 13 | L9: =COUNTA($A$12:$A$120) -> 13 | M9: =COUNTA($A$12:$A$120) -> 13 | N9: =COUNTA($A$12:$A$120) -> 13 | O9: =COUNTA($A$12:$A$120) -> 13 | P9: =COUNTA($A$12:$A$120) -> 13 | ... AM9: =COUNTA($A$12:$A$120) -> 13
H10: Migration Kickoff Tasks | O10: Application Shutdown | S10: Server Shutdown | V10: VM Cutover | AD10: Application Startup | AH10: Application Testing / Migration completion
A11: VM | B11: Function/Role | C11: Move Group | D11: Sequence | E11: OS | F11: VM Migration % Complete | H11: Open Command Bridge and Take Role | I11: Ensure Migration Readiness - Final GO/NO-GO | J11: Confirm Data Replications are completed | K11: Confirm Backups are completed | L11: Confirm T-Minus (T-7 to T-0) are completed | M11: Disable Alerts | N11: Disable the Backup | O11: Complete Application Shutdown Tasks | P11: Complete Database Shutdown Tasks | Q11: Stop the services (various applications) and put them manual startup/Disable mode | R11: Verify that all application/database/service shutdown tasks have been completed | S11: Shutdown the VMs - CMO | T11: Ensure that there is no activity on the VMs in CMO | U11: Verify that the consistency group is in Active (sync) state between CMO & FMO | V11: Enable Image Access on the CG | W11: Power On the VMs of the CG at the FMO | X11: Update internal/external DNS / LB entries as required (If Applicable) | Y11: Perform any remediation required(If Applicable) | Z11: Perform server boot healthcheck on VMs | AA11: Release to OS team for validation | AB11: Validate server tooling | AC11: Handover Server for User Acceptance Testing | AD11: Complete Database Startup Tasks | AE11: Start the services (various applications) and put them automatic startup mode as required | AF11: Complete Application Startup Tasks | AG11: Validate all application startup tasks are complete | AH11: Complete Operational Application Testing per UAT Document | AI11: Validate all application testing completed successfully | AJ11: Enable Direct access on the Consistency Group at FMO | AK11: Cleanup the Consistency Group in RP4VM | AL11: Complete Application Testing (Business Testing) | AM11: Migration Complete Sign Off
A12: ESBBWSVCQ12 | B12: App | C12: Wave 00B | D12: None | E12: Windows | F12: =(COUNTIF(H12:AM12,"Complete")/COUNTA(H12:AM12)+COUNTIF(H12:AM12,"DNM")/COUNTA(H12:AM12))*100 -> 0 | H12: Pending | I12: Pending | J12: Pending | K12: Pending | L12: Pending | M12: Pending | N12: Pending | O12: Pending | P12: Pending | Q12: Pending | R12: Pending | S12: Pending | T12: Pending | U12: Pending | V12: Pending | W12: Pending | X12: Pending | Y12: Pending | Z12: Pending | AA12: Pending | AB12: Pending | AC12: Pending | AD12: Pending | AE12: Pending | AF12: Pending | AG12: Pending | AH12: Pending | AI12: Pending | AJ12: Pending | AK12: Pending | AL12: Pending | AM12: Pending
A13: HRSKROSQLD01 | B13: DB | C13: Wave 00B | D13: None | E13: Windows | F13: =(COUNTIF(H13:AM13,"Complete")/COUNTA(H13:AM13)+COUNTIF(H13:AM13,"DNM")/COUNTA(H13:AM13))*100 -> 0 | H13: Pending | I13: Pending | J13: Pending | K13: Pending | L13: Pending | M13: Pending | N13: Pending | O13: Pending | P13: Pending | Q13: Pending | R13: Pending | S13: Pending | T13: Pending | U13: Pending | V13: Pending | W13: Pending | X13: Pending | Y13: Pending | Z13: Pending | AA13: Pending | AB13: Pending | AC13: Pending | AD13: Pending | AE13: Pending | AF13: Pending | AG13: Pending | AH13: Pending | AI13: Pending | AJ13: Pending | AK13: Pending | AL13: Pending | AM13: Pending
A14: HRSKROWDMD01 | B14: App | C14: Wave 00B | D14: None | E14: Windows | F14: =(COUNTIF(H14:AM14,"Complete")/COUNTA(H14:AM14)+COUNTIF(H14:AM14,"DNM")/COUNTA(H14:AM14))*100 -> 0 | H14: Pending | I14: Pending | J14: Pending | K14: Pending | L14: Pending | M14: Pending | N14: Pending | O14: Pending | P14: Pending | Q14: Pending | R14: Pending | S14: Pending | T14: Pending | U14: Pending | V14: Pending | W14: Pending | X14: Pending | Y14: Pending | Z14: Pending | AA14: Pending | AB14: Pending | AC14: Pending | AD14: Pending | AE14: Pending | AF14: Pending | AG14: Pending | AH14: Pending | AI14: Pending | AJ14: Pending | AK14: Pending | AL14: Pending | AM14: Pending
A15: ESBADMINQ12 | B15: App | C15: Wave 00B | D15: None | E15: Windows | F15: =(COUNTIF(H15:AM15,"Complete")/COUNTA(H15:AM15)+COUNTIF(H15:AM15,"DNM")/COUNTA(H15:AM15))*100 -> 0 | H15: Pending | I15: Pending | J15: Pending | K15: Pending | L15: Pending | M15: Pending | N15: Pending | O15: Pending | P15: Pending | Q15: Pending | R15: Pending | S15: Pending | T15: Pending | U15: Pending | V15: Pending | W15: Pending | X15: Pending | Y15: Pending | Z15: Pending | AA15: Pending | AB15: Pending | AC15: Pending | AD15: Pending | AE15: Pending | AF15: Pending | AG15: Pending | AH15: Pending | AI15: Pending | AJ15: Pending | AK15: Pending | AL15: Pending | AM15: Pending
A16: ESBBWSVCQ13 | B16: App | C16: Wave 00B | D16: None | E16: Windows | F16: =(COUNTIF(H16:AM16,"Complete")/COUNTA(H16:AM16)+COUNTIF(H16:AM16,"DNM")/COUNTA(H16:AM16))*100 -> 0 | H16: Pending | I16: Pending | J16: Pending | K16: Pending | L16: Pending | M16: Pending | N16: Pending | O16: Pending | P16: Pending | Q16: Pending | R16: Pending | S16: Pending | T16: Pending | U16: Pending | V16: Pending | W16: Pending | X16: Pending | Y16: Pending | Z16: Pending | AA16: Pending | AB16: Pending | AC16: Pending | AD16: Pending | AE16: Pending | AF16: Pending | AG16: Pending | AH16: Pending | AI16: Pending | AJ16: Pending | AK16: Pending | AL16: Pending | AM16: Pending
A17: HRSKROWRMD01 | B17: App | C17: Wave 00B | D17: None | E17: Windows | F17: =(COUNTIF(H17:AM17,"Complete")/COUNTA(H17:AM17)+COUNTIF(H17:AM17,"DNM")/COUNTA(H17:AM17))*100 -> 0 | H17: Pending | I17: Pending | J17: Pending | K17: Pending | L17: Pending | M17: Pending | N17: Pending | O17: Pending | P17: Pending | Q17: Pending | R17: Pending | S17: Pending | T17: Pending | U17: Pending | V17: Pending | W17: Pending | X17: Pending | Y17: Pending | Z17: Pending | AA17: Pending | AB17: Pending | AC17: Pending | AD17: Pending | AE17: Pending | AF17: Pending | AG17: Pending | AH17: Pending | AI17: Pending | AJ17: Pending | AK17: Pending | AL17: Pending | AM17: Pending
A18: ESBADMINQ11 | B18: App | C18: Wave 00B | D18: None | E18: Windows | F18: =(COUNTIF(H18:AM18,"Complete")/COUNTA(H18:AM18)+COUNTIF(H18:AM18,"DNM")/COUNTA(H18:AM18))*100 -> 0 | H18: Pending | I18: Pending | J18: Pending | K18: Pending | L18: Pending | M18: Pending | N18: Pending | O18: Pending | P18: Pending | Q18: Pending | R18: Pending | S18: Pending | T18: Pending | U18: Pending | V18: Pending | W18: Pending | X18: Pending | Y18: Pending | Z18: Pending | AA18: Pending | AB18: Pending | AC18: Pending | AD18: Pending | AE18: Pending | AF18: Pending | AG18: Pending | AH18: Pending | AI18: Pending | AJ18: Pending | AK18: Pending | AL18: Pending | AM18: Pending
A19: ESBBWSVCQ11 | B19: App | C19: Wave 00B | D19: None | E19: Windows | F19: =(COUNTIF(H19:AM19,"Complete")/COUNTA(H19:AM19)+COUNTIF(H19:AM19,"DNM")/COUNTA(H19:AM19))*100 -> 0 | H19: Pending | I19: Pending | J19: Pending | K19: Pending | L19: Pending | M19: Pending | N19: Pending | O19: Pending | P19: Pending | Q19: Pending | R19: Pending | S19: Pending | T19: Pending | U19: Pending | V19: Pending | W19: Pending | X19: Pending | Y19: Pending | Z19: Pending | AA19: Pending | AB19: Pending | AC19: Pending | AD19: Pending | AE19: Pending | AF19: Pending | AG19: Pending | AH19: Pending | AI19: Pending | AJ19: Pending | AK19: Pending | AL19: Pending | AM19: Pending
A20: HRSKROAPPD01 | B20: App | C20: Wave 00B | D20: None | E20: Windows | F20: =(COUNTIF(H20:AM20,"Complete")/COUNTA(H20:AM20)+COUNTIF(H20:AM20,"DNM")/COUNTA(H20:AM20))*100 -> 0 | H20: Pending | I20: Pending | J20: Pending | K20: Pending | L20: Pending | M20: Pending | N20: Pending | O20: Pending | P20: Pending | Q20: Pending | R20: Pending | S20: Pending | T20: Pending | U20: Pending | V20: Pending | W20: Pending | X20: Pending | Y20: Pending | Z20: Pending | AA20: Pending | AB20: Pending | AC20: Pending | AD20: Pending | AE20: Pending | AF20: Pending | AG20: Pending | AH20: Pending | AI20: Pending | AJ20: Pending | AK20: Pending | AL20: Pending | AM20: Pending
A21: ESBEMSAPPCLQ11A | B21: App | C21: Wave 00B | D21: None | E21: Windows | F21: =(COUNTIF(H21:AM21,"Complete")/COUNTA(H21:AM21)+COUNTIF(H21:AM21,"DNM")/COUNTA(H21:AM21))*100 -> 0 | H21: Pending | I21: Pending | J21: Pending | K21: Pending | L21: Pending | M21: Pending | N21: Pending | O21: Pending | P21: Pending | Q21: Pending | R21: Pending | S21: Pending | T21: Pending | U21: Pending | V21: Pending | W21: Pending | X21: Pending | Y21: Pending | Z21: Pending | AA21: Pending | AB21: Pending | AC21: Pending | AD21: Pending | AE21: Pending | AF21: Pending | AG21: Pending | AH21: Pending | AI21: Pending | AJ21: Pending | AK21: Pending | AL21: Pending | AM21: Pending
A22: ESBEMSAPPCLQ11B | B22: App | C22: Wave 00B | D22: None | E22: Windows | F22: =(COUNTIF(H22:AM22,"Complete")/COUNTA(H22:AM22)+COUNTIF(H22:AM22,"DNM")/COUNTA(H22:AM22))*100 -> 0 | H22: Pending | I22: Pending | J22: Pending | K22: Pending | L22: Pending | M22: Pending | N22: Pending | O22: Pending | P22: Pending | Q22: Pending | R22: Pending | S22: Pending | T22: Pending | U22: Pending | V22: Pending | W22: Pending | X22: Pending | Y22: Pending | Z22: Pending | AA22: Pending | AB22: Pending | AC22: Pending | AD22: Pending | AE22: Pending | AF22: Pending | AG22: Pending | AH22: Pending | AI22: Pending | AJ22: Pending | AK22: Pending | AL22: Pending | AM22: Pending
A23: ESBEMSMONCLQ11A | B23: App | C23: Wave 00B | D23: None | E23: Windows | F23: =(COUNTIF(H23:AM23,"Complete")/COUNTA(H23:AM23)+COUNTIF(H23:AM23,"DNM")/COUNTA(H23:AM23))*100 -> 0 | H23: Pending | I23: Pending | J23: Pending | K23: Pending | L23: Pending | M23: Pending | N23: Pending | O23: Pending | P23: Pending | Q23: Pending | R23: Pending | S23: Pending | T23: Pending | U23: Pending | V23: Pending | W23: Pending | X23: Pending | Y23: Pending | Z23: Pending | AA23: Pending | AB23: Pending | AC23: Pending | AD23: Pending | AE23: Pending | AF23: Pending | AG23: Pending | AH23: Pending | AI23: Pending | AJ23: Pending | AK23: Pending | AL23: Pending | AM23: Pending
A24: ESBEMSMONCLQ11B | B24: App | C24: Wave 00B | D24: None | E24: Windows | F24: =(COUNTIF(H24:AM24,"Complete")/COUNTA(H24:AM24)+COUNTIF(H24:AM24,"DNM")/COUNTA(H24:AM24))*100 -> 0 | H24: Pending | I24: Pending | J24: Pending | K24: Pending | L24: Pending | M24: Pending | N24: Pending | O24: Pending | P24: Pending | Q24: Pending | R24: Pending | S24: Pending | T24: Pending | U24: Pending | V24: Pending | W24: Pending | X24: Pending | Y24: Pending | Z24: Pending | AA24: Pending | AB24: Pending | AC24: Pending | AD24: Pending | AE24: Pending | AF24: Pending | AG24: Pending | AH24: Pending | AI24: Pending | AJ24: Pending | AK24: Pending | AL24: Pending | AM24: Pending

Sheet Contorl M Migration Activities_
A1: Task # | B1: Activity | C1: Applicability/DC | D1: Task Description | E1: Definition of Done | F1: Performed By | G1: App migration Plan | H1: Comments - APP Team | I1: Readiness/ Automated/manual | J1: Current Status | K1: Evidences
A2: 1 | B2: Pre-Cutover | C2: HK in GDC East Brown Estate | D2: 14th Aug'25 - Brown DC - All jobs during the catalyst cutover window, Highlight all your critical jobs and its impacted app/reports business details - Implement a CR# CHG0820307 on or before 15TH AUG'25 2 PM HKT to mark NONE manual order in Brown PROD (manual deployment control-m team -- refer Misc Details) | E2: -Forecast is taken for 14th Aug'25 - Highlighted in Red all jobs that are critical with their Impacted app/Dependent app and team | F2: App Team/PSS | G2: Forecast for 14th Aug'25 is in the sheet here with all impacted app Downstream and upstream. - Jobs that need to be put on HOLD due to HaaS platform cutover readiness are identified and highlighted in the forecast sheet attached with impacted app details. | H2: Completed | I2: Manual | J2: Completed | K2: N/A
A3: 2 | B3: Pre-Cutover | C3: HK in GDC East Brown Estate | D3: Application Runbook is completed with all the Forecast data for the job to be executed on 15TH Aug'25 in Green DC . All jobs that need to be put on Hold for these dates due to overrun or Cutover time i.e. between 15TH Aug'25 8:00 PM to 16TH Aug'25 2025 7AM HKT are highlighted in the respective app runbook and are linked to the pre-cutover steps section in the runbook. Jobs with downstream dependency and Impact for business needs to be identified and should be part of the application runbook for each of the jobs for the respective app. | E3: Forecast is taken for 15th Aug'25. Highlight the jobs in yellow if jobs that are critical with their Impacted/Dependent application and team. Hold job should be identified in different color or a sheet seperately.t | F3: App Team/PSS | G3: Forecast for 15th Aug'25 is in the sheet here with all impacted app Downstream and upstream. - AS part of Cutover strategy for ODATE 16TH Aug'25, all Control-m jobs in Brown will be marked to manual order by implmenting the CR as part of Step 3 in this doc. - No Manual jobs HOLD required as this will be taken care by CR which will get implemented on 15th Aug before 2 PM HKT. | H3: Completed | I3: Manual | J3: In progress
A4: 3 | B4: Pre-Cutover | C4: HK in GDC East Brown Estate | D4: Change readiness in approved state: Rais a CR for Marking the jobs in Manual order for Green DC. This CR should have 2 task each one for APp team and ATOS team. 1. App Team Task - Add a task in CR to Deploy jobs with NONE manual order using ADO pipeline in Brown DC. - should be performed by respective app team 2. App Team - App team can add a task to ATOS with the implementation plan (mentioned below) their in the runbook link for the following activity. The ATOS task will only be executed if App team fail to deploy using pipeline. The CR should be ready in approved state with above 2 task by 15th July 2025. should be raised and in approved state by 15th Aug 2025 and for the implementation date of 16TH Aug'25. | E4: A CR to be ready with task for app team and backup task for ATOS CR Manual order and change to be implemented by ATOS. To be completed on 15th Aug'25. | F4: App Team/PSS | G4: CR is in New state. - Since every job for ODATE 15th is marked as NONE manual order via CR - CHG0820307, NONE of the jobs will get trigger automatically. Implement this CR only between 11 AM HKT -13 PM HKT in Brown on 15th Aug | H4: CR Drafted . CR: CHG0820307 Start Date:14-08-2025 11 AM HKT End Date:16-08-2025 12 PM HKT you must implement your CR on 15th August before 2 PM PM HKT. -- Please make sure that you get the CR reviewed in draft stage itself with ATOS team before you submit it for approval.
A5: 4 | B5: Pre-Cutover | C5: HK in GDC East Brown Estate | D5: Disable jobs/folders in Brown DC: To mark Jobs Manual NONE order - App team should use their CR as part of task #3 in this sheet to to deploy all jobs with NONE manual order starting 15th Aug'25 in Brown using ADO pipeline. - Failing to do so can use ATOS help to deploy manually. | E5: Needs to be validated on 15th Aug post 2 PM HKT | F5: App Team/PSS | G5: In Progress to be implemented and validated post CR implementation | H5: this needs to be validated on 15th Aug post 2 PM HKT | I5: Manual | J5: Completed
A6: 5 | B6: Pre-Cutover | C6: SG & HK | D6: Green Control-M ready with Automatic schedule configured. Json Files has been prepared with Ordermethod Automatic Before freeze is exercised in Green Control-M site, App teams must Re-Deploy jobs in catalyst Green Control-M with automatic order method via ADO pipleline | E6: 14th Aug'25 - Implement ADO pipeline to deploy in Green with automatic order (Manual task by control-m team -- refer Misc Details page for #RITM) Immediately after that activate WLP to suspend jobs from running in control-m from 15th August onward Note: This will result in jobs getting loaded everyday in control-m with WLP attached so that jobs does not trigger in active environment. This WLP will be valid until you deactivate it. Ideally you will deactive WLP only after GO/NO GO Call on cutover date. | F6: App Team/PSS | G6: In-Progress 14th Aug 2025 - on 14th August run the pipeline to deploy all your control-M jobs in Automatic order in Green. - Activate WLP post the implementation to suspend jobs from running until you deactivate it. 15th Aug 2025 - on 15th Aug at 7:10 AM HKT -8 AM HKT manually HOLD your jobs in Green as well. - you will also delete the jobs which are not supposed to be carried pver to Gereen DC on next day. i.e. you will delete all jobs for ODATE 15th in Green that has completed its run in Brown for ODATE 15th Aug. | H6: NOTE: On 15th and 16th morning between 7:10 AM -7:30 AM HKT put Manual HOLD on all jobs in Green. On 15th Aug please delete all your jobs that does not require rerun in Green DC. (jobs that are scheduled before 4 PM run) | I6: Automatic | J6: Completed
A7: 6 | B7: Pre-Cutover | C7: SG & HK | D7: Agent: ID Vaulting/EBM access and list of agents Agent: ID Vaulting/EBM access and list of agents to be verified. A screenshot confirming the same to be provided to Central team and Control-M team. | E7: - Agent ID is vaulted and verified - A artifect is attached in this runbook. Attach a screenshot of vaulted ID in Word Doc and attach in this section | F7: App Team/PSS | G7: NA since it is going to be centrally taken care by HaaS platform team | H7: NA | I7: Manual | J7: Completed
A8: 7 | B8: Pre-Cutover | C8: SG & HK | D8: Hostgroups Creation and Configuration Host group - VIP DNC approach has been followed Hostgroups - Applications using host group and participation rules should review them in Control-M and sign off post validating the configuration, also need to provide the list of groups as well | E8: - Host Groups should be created and configured in Control-M Site standards - A artifect is attached in this runbook. Attach a screenshot of vaulted ID in Word Doc and attach in this section | F8: App Team/PSS | G8: Task is completed and verified attached the artifects. | H8: Completed | I8: Manual | J8: Completed
A9: 8 | B9: Pre-Cutover | C9: SG & HK | D9: Job owner - Run as user | E9: RunAs - Application teams to verify their RunAs users in their respective site standards | F9: App Team/PSS | G9: Task is completed and verified attached the artifects. | H9: Completed | I9: Manual | J9: Completed
A10: 9 | B10: Pre-Cutover | C10: SG & HK | D10: User Roles access verification | E10: UserRoles - Applications to verify if members from application PSS/DEV teams are tagged to the correct AD groups. | F10: App Team/PSS | G10: Task is completed and verified attached the artifects. | H10: Completed | I10: Manual | J10: Completed
A11: 10 | B11: Pre-Cutover | C11: SG & HK | D11: Site Standard verification | E11: Site Standard - App teams to verify their respective site standards and provide sign off that the details are up to date. Things to validate are primarily as below. Host/VIP names. RunAs ids. | F11: App Team/PSS | G11: Task is completed and verified attached the artifects. | H11: Completed | I11: Manual | J11: Completed
A12: 11 | B12: Pre-Cutover | C12: SG & HK | D12: Calendar Jobs verification Brown <-> Green Application team to login to Control-M and verify that the calendars are up to the date; Liaise with EBM for any updates in Catalyst Green DC | E12: All calendars to be used in Green DC for your jobs are present and validated - A screen shot is attached as a artifects - Calendar details are submitted in this link to Control-M for validation | F12: App Team/PSS | G12: NA - Global calenders used | H12: Global Calender. | I12: NA | J12: NA
A13: 12 | B13: Pre-Cutover | C13: SG & HK | D13: QR verification Application team to login to Control-M and verify that their QR's are available and up to date; Liaise with EBM for any updates in Catalyst Green DC | E13: Application team to login to Control-M and verify that their QR's are available and up to date; Liaise with EBM for any updates in Catalyst Green DC - Not appliable | F13: App Team/PSS | G13: Task is completed and verified attached the artifects. | H13: Its verified and artifecect link is here https://dev.azure.com/sc-ado/TTOQPR/_workitems/edit/9901833 | I13: Manual | J13: Completed | K13: https://dev.azure.com/sc-ado/TTOQPR/_workitems/edit/9901833
A14: 13 | B14: Pre-Cutover | C14: SG & HK | D14: Global Conditions Not applicable for CARD400 Global Condition - Applications using global conditions(condition flow between 2 Control-M servers | E14: Not Applicable | F14: App Team/PSS | G14: Not applicable | I14: NA | J14: NA
A15: 14 | B15: Pre-Cutover | C15: SG & HK | D15: Job Alerts ITRS Job alerting rules: CTM ALERT MAPPING - alert rule mapping details to all applications for them to confirm on the alert routing for batch jobs failures. Liaise with EBM for updates in Catalyst Green DC | E15: - The alert mapping rule shared by EBM has been verified - Any change required in TSO group should be notified and implemented with the help of Control-M team | F15: App Team/PSS | G15: During go live this activity should get kick started | I15: Manual | J15: Yet to Start
A16: 15 | B16: Pre-Cutover | C16: SG & HK | D16: User Daily Job details User Daily - applications who have specific user daily to load their jobs in AJF outside of NDP should share us the user daily details for validation. Detail to share as below: user daily name and the time the jobs should be ordered Liaise with EBM for any updates in Catalyst Green DC | E16: Not Applicable | F16: App Team/PSS | G16: Not applicable | I16: NA | J16: NA
A17: 16 | B17: Pre-Cutover | C17: SG & HK | D17: PSS Team has validated Dynamic WLP in catalyst Green DC Dynamic WLP to be created and kept ready; Liaise with EBM for any updates in Catalyst Green | E17: - Dynamic WLP is created and verified - Artifect is attached. | F17: App Team/PSS | G17: IN Progress | I17: Manual | J17: Yet to Start
A18: 17 | B18: Pre-Cutover | C18: SG & HK | D18: Brown DC to Green DC dependency - Applicable to HaaS dependent apps | E18: Brown DC to Green DC dependency - Applicable to HaaS dependent apps | F18: App Team/PSS | G18: Not applicable | I18: NA | J18: Done
A19: 18 | B19: Cutover | C19: Green DC | D19: 16th Aug - Green DC - Manually order all jobs which were on HOLd in brown for 16TH Aug'25 in Green, complete them. | E19: -Forecast is taken for 16th Aug'25 - Highlighted in Red all jobs that are critical with their Impacted app/Dependent app and team - Jobs were on hold on 16th are part of Green DC forecast list - BVT and tech test cases are associated with all your jobs and its deliverables | F19: App Team/PSS | G19: Forecast is attached for ODATE 16th Aug. - On 16th Aug at 7:10 AM HKT manually hold all your jobs for 16th Aug also. Please NOTE: WLP is still active for your app jobs so you will have to manually HOLD on top of it to make sure all jobs does not start at once. Group A: 9 AM HKT - Release WLP for all jobs at 9 AM HKT once Group A testing is called out to begin. - Run your jobs for (ODATE 15th) in Group A for Test purpose only by releasing them manually (only for the jobs that you want to run as part of testing). ideally some jobs which can assure you that cutover is running fine. Group B: 10 AM HKT - Run your jobs for (ODATE 15th) in Group B for Test purpose only by releasing them manually (the left over job for ODATE 15th to run as part of testing). post GO NO Go Call - Group C Testing - BAU - Release manual HOLD from ODATE 16th Aug JOb to let them run and continue with your BAU. | H19: Completeds | I19: Manual | J19: Yet to Start
A20: 19 | B20: Cutover | C20: Green DC | D20: 17 and 1t8h Aug'25 - Green DC - BAU in Hypercare - Job will execute as per its scheduling criteria | E20: -Forecast is taken for 17 and 18th Aug'25 - Highlighted in yellow all jobs that are critical with their Impacted app/Dependent app and team | F20: App Team/PSS | G20: 17,18th Aug'25 jobs are highlighted in yellow. All BAU in HYPERCARE | H20: Completed | I20: Manual | J20: Yet to Start
A21: 20 | B21: Post Cutover | C21: SG & HK | D21: After successfull go live, work with atos to decom the app in brown Control-M; App team to submit the change as part of their brown dc decom. | E21: Post Go Live - Brown Decomission Activites would be carried out -Change will be raised to ATOS for jobs Decommission | F21: App Team/PSS | G21: we will plan the CR for Decomm of Brown DC Control M jobs post Go live | I21: Manual | J21: Yet to Start

Sheet Atos-Steady State POC's
A1: Name | B1: Stream | C1: Migration day Role/Responsibility | D1: Company | E1: Email id | F1: POC(8 AM to 8 PM ET- 7th Nov) | G1: Hypercare | H1: POC(8 AM to 8 PM ET- 14th Nov) | I1: Hypercare
A2: xxxx (8am to 8pm EST) | B2: Network Core | C2: Oncall | D2: vendor | E2: xxxxx@ABC Crop.com | F2: xxxx | G2: xxxx, xxxx | H2: xxxx | I2: xxxx, xxxx
A3: xxxx | B3: Backup | C3: Oncall | D3: vendor | E3: xxxxx@ABC Crop.com | F3: dl-us-backup-networker dl-us-backup-networker@vendor.net (all except Z1) dl-my-nam-networker bkp team (Z1) | G3: dl-us-backup-networker dl-us-backup-networker@vendor.net (all except Z1) dl-my-nam-networker bkp team (Z1) | H3: dl-us-backup-networker dl-us-backup-networker@vendor.net (all except Z1) dl-my-nam-networker bkp team (Z1) | I3: dl-us-backup-networker dl-us-backup-networker@vendor.net (all except Z1) dl-my-nam-networker bkp team (Z1)
A4: xxxx | B4: VMware Contact during execution | C4: Oncall | D4: vendor | E4: xxxxx@ABC Crop.com | F4: xxxx | G4: xxxx | H4: xxxx | I4: xxxx
A5: xxxx | B5: VMware Contact during execution | C5: Oncall | D5: vendor | E5: xxxxx@ABC Crop.com | F5: xxxx | G5: xxxx | H5: xxxx | I5: xxxx
A6: xxxx | B6: DNS | C6: Oncall | D6: vendor | E6: xxxxx@ABC Crop.com | F6: xxxx, dl-netman@vendor.net. | G6: xxxx, dl-netman@vendor.net. | H6: xxxx, dl-netman@vendor.net. | I6: xxxx, dl-netman@vendor.net.
A7: xxxx | B7: DNS | C7: Oncall | D7: vendor | E7: xxxxx@ABC Crop.com | F7: xxxx | G7: xxxx, dl-netman@vendor.net. | H7: xxxx, dl-netman@vendor.net. | I7: xxxx, dl-netman@vendor.net.
A8: xxxx | B8: Project Manager (vendor) | C8: Required to Oversee Migration | D8: vendor | E8: xxxxx@ABC Crop.com | F8: xxxx | G8: xxxx | H8: xxxx | I8: xxxx
A9: xxxx Long | B9: Windows Team | C9: Oncall | D9: vendor | E9: xxxxx@ABC Crop.com | F9: xxxx Long | G9: xxxx Long | H9: xxxx Long | I9: xxxx Long
A10: xxxx | B10: Windows Team | C10: Oncall | D10: vendor | E10: xxxxx@ABC Crop.com | F10: xxxx | G10: xxxx | H10: xxxx | I10: xxxx
A11: xxxx | B11: Database - SQL | C11: Oncall | D11: vendor | E11: xxxxx@ABC Crop.com | F11: xxxx | G11: xxxx | H11: xxxx | I11: xxxx
A12: xxxx | B12: SCOM for Active Directory Monitoring | C12: Not used by ABC Crop | D12: vendor | E12: xxxxx@ABC Crop.com | F12: Contact not required for Migration | G12: Contact not required for Migration | H12: Contact not required for Migration | I12: Contact not required for Migration
... A23: xxxx | B23: Windows Team | C23: Oncall | D23: Steady State | E23: xxxxx@ABC Crop.com | F23: DL-ABC Crop-Windows@vendor.net | G23: DL-ABC Crop-Windows@vendor.net | H23: DL-ABC Crop-Windows@vendor.net | I23: DL-ABC Crop-Windows@vendor.net

Sheet Contact Numbers
A1: Name | B1: Company | C1: Role | D1: Email ID | E1: Contact
A2: xxxx | B2: ABC Crop | C2: App Contacts | D2: xxxxx@ABC Crop.com | E2: xxx-xxx-xxxx
